Workbook
Name Margin: _xlfn.LAMBDA(_xlpm.price,_xlpm.cost, (_xlpm.price - _xlpm.cost) / _xlpm.price)
Name MinOrder: Settings!$B$5
Name QuarterOf: _xlfn.LAMBDA(_xlpm.date, "Q" & ROUNDUP(MONTH(_xlpm.date) / 3, 0))
Name ReportEnd: Settings!$B$4
Name ReportStart: Settings!$B$3
Name TaxRate: Settings!$B$2
Name WithTax: _xlfn.LAMBDA(_xlpm.amount,_xlop.rate, _xlpm.amount * (1 + IF(_xlfn.ISOMITTED(_xlpm.rate), TaxRate, _xlpm.rate)))

Sheet Start here
A1: Cellsmith Academy practice workbook
A3: This workbook goes with the free course at itsdaniyalm.github.io/cellsmith-academy
A5: Data sheets (used by every example in the book):
A6: Sales 48 orders from Brightside Supply Co., January to June 2026 (table: Sales)
A7: Products 8 products with price and cost (table: Products)
A8: Staff 8 sales reps (table: Staff)
A9: Leads 6 messy contact records for the text chapter (table: Leads)
A10: Targets quarterly revenue targets by region (table: Targets)
A11: Tiers commission rates by sales band (table: Tiers)
A12: Settings named cells TaxRate, ReportStart, ReportEnd and MinOrder
A14: Exercise sheets are named after chapters (A1, A2, B1 ...). Type a formula in a yellow cell;
A15: the check below it shows Correct when the result matches. Answers are in the book.
A17: Made by Muhammad Daniyal. Free to use and share under CC BY 4.0.

Sheet Sales
A1: Order ID | B1: Date | C1: Region | D1: Rep | E1: SKU | F1: Product | G1: Units | H1: Price | I1: Discount | J1: Revenue | K1: Status | L1: Ship Date
A2: SO-1001 | B2: 46024 | C2: East | D2: Elena | E2: BS-103 | F2: Gel Pen Set | G2: 28 | H2: 9 | I2: 0.15 | J2: =ROUND(Sales[[#This Row],[Units]]*Sales[[#This Row],[Price]]*(1-Sales[[#This Row],[Discount]]),2) -> 214.2 | K2: Closed | L2: 46031
A3: SO-1002 | B3: 46027 | C3: West | D3: Grace | E3: BS-103 | F3: Gel Pen Set | G3: 14 | H3: 9 | I3: 0.05 | J3: =ROUND(Sales[[#This Row],[Units]]*Sales[[#This Row],[Price]]*(1-Sales[[#This Row],[Discount]]),2) -> 119.7 | K3: Open
A4: SO-1003 | B4: 46031 | C4: West | D4: Grace | E4: BS-101 | F4: Desk Lamp | G4: 6 | H4: 34 | I4: 0.05 | J4: =ROUND(Sales[[#This Row],[Units]]*Sales[[#This Row],[Price]]*(1-Sales[[#This Row],[Discount]]),2) -> 193.8 | K4: Closed | L4: 46033
A5: SO-1004 | B5: 46035 | C5: North | D5: Ben | E5: BS-102 | F5: Notebook | G5: 55 | H5: 6.5 | I5: 0 | J5: =ROUND(Sales[[#This Row],[Units]]*Sales[[#This Row],[Price]]*(1-Sales[[#This Row],[Discount]]),2) -> 357.5 | K5: Closed | L5: 46042
A6: SO-1005 | B6: 46038 | C6: East | D6: Farid | E6: BS-104 | F6: Monitor Stand | G6: 5 | H6: 49 | I6: 0 | J6: =ROUND(Sales[[#This Row],[Units]]*Sales[[#This Row],[Price]]*(1-Sales[[#This Row],[Discount]]),2) -> 245 | K6: Open
A7: SO-1006 | B7: 46042 | C7: North | D7: Ben | E7: BS-106 | F7: Cable Kit | G7: 16 | H7: 14 | I7: 0 | J7: =ROUND(Sales[[#This Row],[Units]]*Sales[[#This Row],[Price]]*(1-Sales[[#This Row],[Discount]]),2) -> 224 | K7: Closed | L7: 46049
A8: SO-1007 | B8: 46046 | C8: East | D8: Elena | E8: BS-101 | F8: Desk Lamp | G8: 11 | H8: 34 | I8: 0 | J8: =ROUND(Sales[[#This Row],[Units]]*Sales[[#This Row],[Price]]*(1-Sales[[#This Row],[Discount]]),2) -> 374 | K8: Closed | L8: 46049
A9: SO-1008 | B9: 46049 | C9: North | D9: Ava | E9: BS-101 | F9: Desk Lamp | G9: 4 | H9: 34 | I9: 0.1 | J9: =ROUND(Sales[[#This Row],[Units]]*Sales[[#This Row],[Price]]*(1-Sales[[#This Row],[Discount]]),2) -> 122.4 | K9: Closed | L9: 46054
A10: SO-1009 | B10: 46053 | C10: East | D10: Farid | E10: BS-106 | F10: Cable Kit | G10: 9 | H10: 14 | I10: 0 | J10: =ROUND(Sales[[#This Row],[Units]]*Sales[[#This Row],[Price]]*(1-Sales[[#This Row],[Discount]]),2) -> 126 | K10: Closed | L10: 46055
A11: SO-1010 | B11: 46057 | C11: West | D11: Grace | E11: BS-106 | F11: Cable Kit | G11: 15 | H11: 14 | I11: 0 | J11: =ROUND(Sales[[#This Row],[Units]]*Sales[[#This Row],[Price]]*(1-Sales[[#This Row],[Discount]]),2) -> 210 | K11: Closed | L11: 46060
A12: SO-1011 | B12: 46061 | C12: East | D12: Elena | E12: BS-103 | F12: Gel Pen Set | G12: 30 | H12: 9 | I12: 0.05 | J12: =ROUND(Sales[[#This Row],[Units]]*Sales[[#This Row],[Price]]*(1-Sales[[#This Row],[Discount]]),2) -> 256.5 | K12: Closed | L12: 46065
A13: SO-1012 | B13: 46064 | C13: East | D13: Elena | E13: BS-106 | F13: Cable Kit | G13: 23 | H13: 14 | I13: 0.1 | J13: =ROUND(Sales[[#This Row],[Units]]*Sales[[#This Row],[Price]]*(1-Sales[[#This Row],[Discount]]),2) -> 289.8 | K13: Closed | L13: 46066
A14: SO-1013 | B14: 46068 | C14: North | D14: Ben | E14: BS-108 | F14: Whiteboard | G14: 5 | H14: 79 | I14: 0.1 | J14: =ROUND(Sales[[#This Row],[Units]]*Sales[[#This Row],[Price]]*(1-Sales[[#This Row],[Discount]]),2) -> 355.5 | K14: Closed | L14: 46071
A15: SO-1014 | B15: 46072 | C15: West | D15: Hiro | E15: BS-101 | F15: Desk Lamp | G15: 4 | H15: 34 | I15: 0 | J15: =ROUND(Sales[[#This Row],[Units]]*Sales[[#This Row],[Price]]*(1-Sales[[#This Row],[Discount]]),2) -> 136 | K15: Closed | L15: 46078
A16: SO-1015 | B16: 46075 | C16: West | D16: Grace | E16: BS-105 | F16: Desk Chair | G16: 3 | H16: 189 | I16: 0 | J16: =ROUND(Sales[[#This Row],[Units]]*Sales[[#This Row],[Price]]*(1-Sales[[#This Row],[Discount]]),2) -> 567 | K16: Closed | L16: 46082
A17: SO-1016 | B17: 46079 | C17: South | D17: Chloe | E17: BS-106 | F17: Cable Kit | G17: 17 | H17: 14 | I17: 0 | J17: =ROUND(Sales[[#This Row],[Units]]*Sales[[#This Row],[Price]]*(1-Sales[[#This Row],[Discount]]),2) -> 238 | K17: Closed | L17: 46080
A18: SO-1017 | B18: 46083 | C18: East | D18: Elena | E18: BS-101 | F18: Desk Lamp | G18: 11 | H18: 34 | I18: 0 | J18: =ROUND(Sales[[#This Row],[Units]]*Sales[[#This Row],[Price]]*(1-Sales[[#This Row],[Discount]]),2) -> 374 | K18: Closed | L18: 46090
... A20: SO-1019 | B20: 46090 | C20: South | D20: Dev | E20: BS-104 | F20: Monitor Stand | G20: 7 | H20: 49 | I20: 0 | J20: =ROUND(Sales[[#This Row],[Units]]*Sales[[#This Row],[Price]]*(1-Sales[[#This Row],[Discount]]),2) -> 343 | K20: Closed | L20: 46091
A21: SO-1020 | B21: 46094 | C21: West | D21: Grace | E21: BS-106 | F21: Cable Kit | G21: 25 | H21: 14 | I21: 0 | J21: =ROUND(Sales[[#This Row],[Units]]*Sales[[#This Row],[Price]]*(1-Sales[[#This Row],[Discount]]),2) -> 350 | K21: Open
A22: SO-1021 | B22: 46098 | C22: South | D22: Chloe | E22: BS-103 | F22: Gel Pen Set | G22: 24 | H22: 9 | I22: 0.15 | J22: =ROUND(Sales[[#This Row],[Units]]*Sales[[#This Row],[Price]]*(1-Sales[[#This Row],[Discount]]),2) -> 183.6 | K22: Closed | L22: 46104
A23: SO-1022 | B23: 46101 | C23: North | D23: Ava | E23: BS-106 | F23: Cable Kit | G23: 12 | H23: 14 | I23: 0.1 | J23: =ROUND(Sales[[#This Row],[Units]]*Sales[[#This Row],[Price]]*(1-Sales[[#This Row],[Discount]]),2) -> 151.2 | K23: Closed | L23: 46102
A24: SO-1023 | B24: 46105 | C24: North | D24: Ben | E24: BS-104 | F24: Monitor Stand | G24: 7 | H24: 49 | I24: 0 | J24: =ROUND(Sales[[#This Row],[Units]]*Sales[[#This Row],[Price]]*(1-Sales[[#This Row],[Discount]]),2) -> 343 | K24: Closed | L24: 46109
A25: SO-1024 | B25: 46109 | C25: West | D25: Hiro | E25: BS-105 | F25: Desk Chair | G25: 3 | H25: 189 | I25: 0 | J25: =ROUND(Sales[[#This Row],[Units]]*Sales[[#This Row],[Price]]*(1-Sales[[#This Row],[Discount]]),2) -> 567 | K25: Closed | L25: 46111
A26: SO-1025 | B26: 46112 | C26: South | D26: Dev | E26: BS-105 | F26: Desk Chair | G26: 2 | H26: 189 | I26: 0.15 | J26: =ROUND(Sales[[#This Row],[Units]]*Sales[[#This Row],[Price]]*(1-Sales[[#This Row],[Discount]]),2) -> 321.3 | K26: Closed | L26: 46116
A27: SO-1026 | B27: 46116 | C27: North | D27: Ben | E27: BS-102 | F27: Notebook | G27: 2 | H27: 6.5 | I27: 0 | J27: =ROUND(Sales[[#This Row],[Units]]*Sales[[#This Row],[Price]]*(1-Sales[[#This Row],[Discount]]),2) -> 13 | K27: Closed | L27: 46118
A28: SO-1027 | B28: 46120 | C28: South | D28: Chloe | E28: BS-107 | F28: Sticky Notes | G28: 51 | H28: 4.25 | I28: 0 | J28: =ROUND(Sales[[#This Row],[Units]]*Sales[[#This Row],[Price]]*(1-Sales[[#This Row],[Discount]]),2) -> 216.75 | K28: Closed | L28: 46124
A29: SO-1028 | B29: 46123 | C29: East | D29: Elena | E29: BS-105 | F29: Desk Chair | G29: 3 | H29: 189 | I29: 0 | J29: =ROUND(Sales[[#This Row],[Units]]*Sales[[#This Row],[Price]]*(1-Sales[[#This Row],[Discount]]),2) -> 567 | K29: Closed | L29: 46128
A30: SO-1029 | B30: 46127 | C30: East | D30: Farid | E30: BS-103 | F30: Gel Pen Set | G30: 36 | H30: 9 | I30: 0 | J30: =ROUND(Sales[[#This Row],[Units]]*Sales[[#This Row],[Price]]*(1-Sales[[#This Row],[Discount]]),2) -> 324 | K30: Cancelled
A31: SO-1030 | B31: 46131 | C31: East | D31: Farid | E31: BS-101 | F31: Desk Lamp | G31: 7 | H31: 34 | I31: 0 | J31: =ROUND(Sales[[#This Row],[Units]]*Sales[[#This Row],[Price]]*(1-Sales[[#This Row],[Discount]]),2) -> 238 | K31: Closed | L31: 46138
A32: SO-1031 | B32: 46135 | C32: South | D32: Dev | E32: BS-108 | F32: Whiteboard | G32: 3 | H32: 79 | I32: 0.1 | J32: =ROUND(Sales[[#This Row],[Units]]*Sales[[#This Row],[Price]]*(1-Sales[[#This Row],[Discount]]),2) -> 213.3 | K32: Closed | L32: 46140
A33: SO-1032 | B33: 46138 | C33: North | D33: Ava | E33: BS-107 | F33: Sticky Notes | G33: 50 | H33: 4.25 | I33: 0 | J33: =ROUND(Sales[[#This Row],[Units]]*Sales[[#This Row],[Price]]*(1-Sales[[#This Row],[Discount]]),2) -> 212.5 | K33: Closed | L33: 46139
A34: SO-1033 | B34: 46142 | C34: West | D34: Hiro | E34: BS-108 | F34: Whiteboard | G34: 5 | H34: 79 | I34: 0.15 | J34: =ROUND(Sales[[#This Row],[Units]]*Sales[[#This Row],[Price]]*(1-Sales[[#This Row],[Discount]]),2) -> 335.75 | K34: Closed | L34: 46149
A35: SO-1034 | B35: 46146 | C35: South | D35: Dev | E35: BS-105 | F35: Desk Chair | G35: 1 | H35: 189 | I35: 0 | J35: =ROUND(Sales[[#This Row],[Units]]*Sales[[#This Row],[Price]]*(1-Sales[[#This Row],[Discount]]),2) -> 189 | K35: Closed | L35: 46149
A36: SO-1035 | B36: 46149 | C36: South | D36: Dev | E36: BS-102 | F36: Notebook | G36: 43 | H36: 6.5 | I36: 0.1 | J36: =ROUND(Sales[[#This Row],[Units]]*Sales[[#This Row],[Price]]*(1-Sales[[#This Row],[Discount]]),2) -> 251.55 | K36: Closed | L36: 46153
A37: SO-1036 | B37: 46153 | C37: North | D37: Ava | E37: BS-108 | F37: Whiteboard | G37: 1 | H37: 79 | I37: 0.05 | J37: =ROUND(Sales[[#This Row],[Units]]*Sales[[#This Row],[Price]]*(1-Sales[[#This Row],[Discount]]),2) -> 75.05 | K37: Closed | L37: 46158
A38: SO-1037 | B38: 46157 | C38: North | D38: Ben | E38: BS-108 | F38: Whiteboard | G38: 1 | H38: 79 | I38: 0 | J38: =ROUND(Sales[[#This Row],[Units]]*Sales[[#This Row],[Price]]*(1-Sales[[#This Row],[Discount]]),2) -> 79 | K38: Closed | L38: 46164
A39: SO-1038 | B39: 46160 | C39: East | D39: Elena | E39: BS-107 | F39: Sticky Notes | G39: 29 | H39: 4.25 | I39: 0 | J39: =ROUND(Sales[[#This Row],[Units]]*Sales[[#This Row],[Price]]*(1-Sales[[#This Row],[Discount]]),2) -> 123.25 | K39: Closed | L39: 46161
A40: SO-1039 | B40: 46164 | C40: South | D40: Chloe | E40: BS-105 | F40: Desk Chair | G40: 3 | H40: 189 | I40: 0 | J40: =ROUND(Sales[[#This Row],[Units]]*Sales[[#This Row],[Price]]*(1-Sales[[#This Row],[Discount]]),2) -> 567 | K40: Closed | L40: 46165
A41: SO-1040 | B41: 46168 | C41: East | D41: Elena | E41: BS-101 | F41: Desk Lamp | G41: 1 | H41: 34 | I41: 0 | J41: =ROUND(Sales[[#This Row],[Units]]*Sales[[#This Row],[Price]]*(1-Sales[[#This Row],[Discount]]),2) -> 34 | K41: Closed | L41: 46173
...

Sheet Products
A1: SKU | B1: Product | C1: Category | D1: Price | E1: Cost
A2: BS-101 | B2: Desk Lamp | C2: Lighting | D2: 34 | E2: 15.5
A3: BS-102 | B3: Notebook | C3: Paper | D3: 6.5 | E3: 2.1
A4: BS-103 | B4: Gel Pen Set | C4: Writing | D4: 9 | E4: 3.4
A5: BS-104 | B5: Monitor Stand | C5: Furniture | D5: 49 | E5: 27
A6: BS-105 | B6: Desk Chair | C6: Furniture | D6: 189 | E6: 112
A7: BS-106 | B7: Cable Kit | C7: Accessories | D7: 14 | E7: 5.2
A8: BS-107 | B8: Sticky Notes | C8: Paper | D8: 4.25 | E8: 1.3
A9: BS-108 | B9: Whiteboard | C9: Furniture | D9: 79 | E9: 41

Sheet Staff
A1: Rep | B1: Name | C1: Email | D1: Region | E1: Hire Date
A2: Ava | B2: Ava Thompson | C2: ava.thompson@brightside.example | D2: North | E2: 43535
A3: Ben | B3: Benjamin Okafor | C3: ben.okafor@brightside.example | D3: North | E3: 44410
A4: Chloe | B4: Chloe Martin | C4: chloe.martin@brightside.example | D4: South | E4: 43115
A5: Dev | B5: Devendra Rao | C5: dev.rao@brightside.example | D5: South | E5: 45068
A6: Elena | B6: Elena Petrova | C6: elena.petrova@brightside.example | D6: East | E6: 44109
A7: Farid | B7: Farid Haddad | C7: farid.haddad@brightside.example | D7: East | E7: 44606
A8: Grace | B8: Grace Lee | C8: grace.lee@brightside.example | D8: West | E8: 42916
A9: Hiro | B9: Hiro Tanaka | C9: hiro.tanaka@brightside.example | D9: West | E9: 45544

Sheet Leads
A1: Lead | B1: Name | C1: Company | D1: Location | E1: Phone | F1: Source
A2: L-01 | B2: maria GARCIA | C2: Harbor & Pine | D2: Austin, TX | E2: (512) 555-0142 | F2: Web
A3: L-02 | B3: james o'neil | C3: Redwood Analytics | D3: Denver, CO | E3: 720.555.0199 | F3: Referral
A4: L-03 | B4: PRIYA SHARMA | C4: Bluefin Logistics | D4: Seattle, WA | E4: 206 555 0175 | F4: Web
A5: L-04 | B5: li wei | C5: Copperleaf Studio | D5: Boston, MA | E5: 617-555-0123 | F5: Event
A6: L-05 | B6: Sofia Rossi | C6: Northgate Clinic | D6: Chicago, IL | E6: +1 312 555 0110 | F6: Web
A7: L-06 | B7: noah johnson | C7: Summit Foods | D7: Miami, FL | E7: (305)555-0166 | F7: Referral

Sheet Targets
A1: Region | B1: Quarter | C1: Target
A2: North | B2: Q1 | C2: 1500
A3: South | B3: Q1 | C3: 1200
A4: East | B4: Q1 | C4: 1800
A5: West | B5: Q1 | C5: 1500
A6: North | B6: Q2 | C6: 1200
A7: South | B7: Q2 | C7: 1500
A8: East | B8: Q2 | C8: 1200
A9: West | B9: Q2 | C9: 1000

Sheet Tiers
A1: Min Sales | B1: Rate
A2: 0 | B2: 0.02
A3: 2000 | B3: 0.04
A4: 5000 | B4: 0.06
A5: 8000 | B5: 0.08

Sheet Settings
A1: Setting | B1: Value
A2: Tax rate | B2: 0.0825
A3: Report start | B3: 46023
A4: Report end | B4: 46203
A5: Minimum order | B5: 100

Sheet Answers
A1: A1 #1 | B1: =COUNTA(Sales[Order ID]) -> 48
A3: A1 #2 | B3: =SUM(Sales[Units]) -> 682
A5: A1 #3 | B5: =DATE(2026, 6, 30) - DATE(2026, 1, 1) -> 180
A7: A1 #4 | B7: =ISNUMBER("682") -> FALSE
A9: A2 #1 | B9: =Settings!B5 -> 100
A11: A2 #2 | B11: =SUM(Sales[Revenue]) * TaxRate -> 972.1635
A13: A2 #3 | B13: =ROWS(Products[]) -> 8
A15: A2 #4 | B15: =AVERAGE(Products[Cost]) -> 25.9375
A17: A3 #1 | B17: {=SUM(Sales[Units] * Sales[Price])} -> 12199.25
A19: A3 #2 | B19: ="Total units: " & SUM(Sales[Units]) -> Total units: 682
A21: A3 #3 | B21: =ROUND(SUM(Sales[Revenue]) * (1 + TaxRate), 2) -> 12755.96
A23: A3 #4 | B23: {=SUM(Sales[Units] * Sales[Price]) - SUM(Sales[Revenue])} -> 415.45
A25: A4 #1 | B25: =MAX(Sales[Revenue]) -> 567
A27: A4 #2 | B27: =ROUND(AVERAGE(Sales[Units]), 1) -> 14.2
A29: A4 #3 | B29: =COUNTBLANK(Sales[Ship Date]) -> 7
A31: A4 #4 | B31: =TEXT(MAX(Sales[Date]), "d mmm yyyy") -> 24 Jun 2026
A33: A4 #5 | B33: =MEDIAN(Sales[Revenue]) -> 228.875
A35: B1 #1 | B35: =IF(SUM(Sales[Revenue]) >= 12000, "Target met", "Short by " & TEXT(12000 - SUM(Sales[Revenue]), "#,##0.00")) -> Short by 216.20
A37: B1 #2 | B37: {=SUM((Sales[Region] = "East") * (Sales[Status] = "Closed"))} -> 12
A39: B1 #3 | B39: {=_xlfn.IFS(AVERAGE(Sales[Discount]) = 0, "None", AVERAGE(Sales[Discount]) < 0.05, "Light", TRUE, "Heavy")} -> Light
A41: B1 #4 | B41: {=SUM(--(Sales[Units] >= 20))} -> 13
A43: B1 #5 | B43: {=SUM(IF(Sales[Status] <> "Cancelled", Sales[Revenue], 0))} -> 10868.15
A45: B2 #1 | B45: =SUMIFS(Sales[Revenue], Sales[Region], "East", Sales[Status], "Closed") -> 2927.85
A47: B2 #2 | B47: =COUNTIFS(Sales[Date], ">=" & DATE(2026, 1, 1), Sales[Date], "<" & DATE(2026, 4, 1)) -> 25
A49: B2 #3 | B49: =AVERAGEIFS(Sales[Revenue], Sales[Discount], ">0") -> 201.05526
A51: B2 #4 | B51: =_xlfn.MINIFS(Sales[Units], Sales[Rep], "Hiro") -> 3
A53: B2 #5 | B53: {=SUM(SUMIFS(Sales[Revenue], Sales[Product], {"Monitor Stand","Desk Chair","Whiteboard"}))} -> 5410.05
A55: B2 #6 | B55: =COUNTIFS(Sales[Status], "<>Cancelled") -> 45
A57: B3 #1 | B57: {=PROPER(TRIM(Leads[Name]))} -> Maria Garcia
B58: James O'Neil
B59: Priya Sharma
B60: Li Wei
B61: Sofia Rossi
B62: Noah Johnson
A64: B3 #2 | B64: {=_xlfn.TEXTAFTER(Leads[Location], ", ")} -> TX
B65: CO
B66: WA
B67: MA
B68: IL
B69: FL
...

Sheet A1
A1: A1 How Excel thinks
A2: Type your formula in each yellow cell. The check below it turns green when your result matches.
A4: Exercise 1 | B4: How many orders are there in the Sales table? Count the Order ID column.
A5: Your formula
A6: =IF(ISBLANK(B5),"",IF(IFERROR(AND(B5=Answers!$B$1),FALSE),"✓ Correct","Not yet"))
A8: Exercise 2 | B8: What is the total number of units sold across all orders?
A9: Your formula
A10: =IF(ISBLANK(B9),"",IF(IFERROR(AND(B9=Answers!$B$3),FALSE),"✓ Correct","Not yet"))
A12: Exercise 3 | B12: How many days are there from 1 January 2026 to 30 June 2026? Use DATE to build both dates and subtract.
A13: Your formula
A14: =IF(ISBLANK(B13),"",IF(IFERROR(AND(B13=Answers!$B$5),FALSE),"✓ Correct","Not yet"))
A16: Exercise 4 | B16: Is the text "682" a number? Write a formula that returns FALSE.
A17: Your formula
A18: =IF(ISBLANK(B17),"",IF(IFERROR(AND(B17=Answers!$B$7),FALSE),"✓ Correct","Not yet"))

Sheet A2
A1: A2 References
A2: Type your formula in each yellow cell. The check below it turns green when your result matches.
A4: Exercise 1 | B4: What is the minimum order value stored in cell B5 of the Settings sheet?
A5: Your formula
A6: =IF(ISBLANK(B5),"",IF(IFERROR(AND(B5=Answers!$B$9),FALSE),"✓ Correct","Not yet"))
A8: Exercise 2 | B8: How much tax would be due on all revenue? Multiply the total of the Revenue column by the named cell TaxRate.
A9: Your formula
A10: =IF(ISBLANK(B9),"",IF(IFERROR(AND(B9=Answers!$B$11),FALSE),"✓ Correct","Not yet"))
A12: Exercise 3 | B12: How many products are in the Products table? Use a structured reference to the whole table.
A13: Your formula
A14: =IF(ISBLANK(B13),"",IF(IFERROR(AND(B13=Answers!$B$13),FALSE),"✓ Correct","Not yet"))
A16: Exercise 4 | B16: What is the average cost of a product?
A17: Your formula
A18: =IF(ISBLANK(B17),"",IF(IFERROR(AND(B17=Answers!$B$15),FALSE),"✓ Correct","Not yet"))

Sheet A3
A1: A3 Operators and order
A2: Type your formula in each yellow cell. The check below it turns green when your result matches.
A4: Exercise 1 | B4: What is the total value of all orders before discounts? Multiply the Units column by the Price column and add up the results.
A5: Your formula
A6: =IF(ISBLANK(B5),"",IF(IFERROR(AND(B5=Answers!$B$17),FALSE),"✓ Correct","Not yet"))
A8: Exercise 2 | B8: Write a formula that returns the text Total units: 682, calculating the number from the Sales table.
A9: Your formula
A10: =IF(ISBLANK(B9),"",IF(IFERROR(AND(B9=Answers!$B$19),FALSE),"✓ Correct","Not yet"))
A12: Exercise 3 | B12: How much revenue would there be including tax? Add TaxRate to the total revenue (multiply by one plus the rate) and round to 2 decimal places with ROUND(value, 2).
A13: Your formula
A14: =IF(ISBLANK(B13),"",IF(IFERROR(AND(B13=Answers!$B$21),FALSE),"✓ Correct","Not yet"))
A16: Exercise 4 | B16: How much did discounts cost the business? Subtract total revenue from the value before discounts.
A17: Your formula
A18: =IF(ISBLANK(B17),"",IF(IFERROR(AND(B17=Answers!$B$23),FALSE),"✓ Correct","Not yet"))

Sheet A4
A1: A4 Reading and writing functions
A2: Type your formula in each yellow cell. The check below it turns green when your result matches.
A4: Exercise 1 | B4: What is the revenue of the largest single order?
A5: Your formula
A6: =IF(ISBLANK(B5),"",IF(IFERROR(AND(B5=Answers!$B$25),FALSE),"✓ Correct","Not yet"))
A8: Exercise 2 | B8: What is the average number of units per order, rounded to one decimal place?
A9: Your formula
A10: =IF(ISBLANK(B9),"",IF(IFERROR(AND(B9=Answers!$B$27),FALSE),"✓ Correct","Not yet"))
A12: Exercise 3 | B12: How many orders haven't shipped yet? Count the empty cells in the Ship Date column.
A13: Your formula
A14: =IF(ISBLANK(B13),"",IF(IFERROR(AND(B13=Answers!$B$29),FALSE),"✓ Correct","Not yet"))
A16: Exercise 4 | B16: Show the date of the most recent order as text like 1 Mar 2026.
A17: Your formula
A18: =IF(ISBLANK(B17),"",IF(IFERROR(AND(B17=Answers!$B$31),FALSE),"✓ Correct","Not yet"))
A20: Exercise 5 | B20: What is the median order revenue? It's less affected by one very large order than the average is.
A21: Your formula
A22: =IF(ISBLANK(B21),"",IF(IFERROR(AND(B21=Answers!$B$33),FALSE),"✓ Correct","Not yet"))

Sheet B1
A1: B1 Making decisions
A2: Type your formula in each yellow cell. The check below it turns green when your result matches.
A4: Exercise 1 | B4: If total revenue is at least 12,000 return Target met, otherwise return Short by followed by the shortfall with two decimal places.
A5: Your formula
A6: =IF(ISBLANK(B5),"",IF(IFERROR(AND(B5=Answers!$B$35),FALSE),"✓ Correct","Not yet"))
A8: Exercise 2 | B8: How many orders are closed and in the East region? Multiply two conditions and add up the result.
A9: Your formula
A10: =IF(ISBLANK(B9),"",IF(IFERROR(AND(B9=Answers!$B$37),FALSE),"✓ Correct","Not yet"))
A12: Exercise 3 | B12: Label the average discount: None if it's 0, Light if it's under 5%, and Heavy otherwise. Use IFS.
A13: Your formula
A14: =IF(ISBLANK(B13),"",IF(IFERROR(AND(B13=Answers!$B$39),FALSE),"✓ Correct","Not yet"))
A16: Exercise 4 | B16: How many orders were for 20 units or more? Count them with a comparison and --.
A17: Your formula
A18: =IF(ISBLANK(B17),"",IF(IFERROR(AND(B17=Answers!$B$41),FALSE),"✓ Correct","Not yet"))
A20: Exercise 5 | B20: What is the total revenue of orders that are not cancelled? Use IF on the whole column.
A21: Your formula
A22: =IF(ISBLANK(B21),"",IF(IFERROR(AND(B21=Answers!$B$43),FALSE),"✓ Correct","Not yet"))

Sheet B2
A1: B2 Counting and summing with conditions
A2: Type your formula in each yellow cell. The check below it turns green when your result matches.
A4: Exercise 1 | B4: What is the total revenue from closed orders in the East region?
A5: Your formula
A6: =IF(ISBLANK(B5),"",IF(IFERROR(AND(B5=Answers!$B$45),FALSE),"✓ Correct","Not yet"))
A8: Exercise 2 | B8: How many orders were placed in the first quarter (January to March 2026)?
A9: Your formula
A10: =IF(ISBLANK(B9),"",IF(IFERROR(AND(B9=Answers!$B$47),FALSE),"✓ Correct","Not yet"))
A12: Exercise 3 | B12: What is the average revenue of orders that had a discount?
A13: Your formula
A14: =IF(ISBLANK(B13),"",IF(IFERROR(AND(B13=Answers!$B$49),FALSE),"✓ Correct","Not yet"))
A16: Exercise 4 | B16: What was Hiro's smallest order, in units?
A17: Your formula
A18: =IF(ISBLANK(B17),"",IF(IFERROR(AND(B17=Answers!$B$51),FALSE),"✓ Correct","Not yet"))
A20: Exercise 5 | B20: What is the total revenue of all orders for Furniture products? The Sales table has no Category column, so match the three furniture products by name: Monitor Stand, Desk Chair and Whiteboard.
A21: Your formula
A22: =IF(ISBLANK(B21),"",IF(IFERROR(AND(B21=Answers!$B$53),FALSE),"✓ Correct","Not yet"))
A24: Exercise 6 | B24: How many orders are not cancelled? Use COUNTIFS with a "not equal" criterion.
A25: Your formula
A26: =IF(ISBLANK(B25),"",IF(IFERROR(AND(B25=Answers!$B$55),FALSE),"✓ Correct","Not yet"))

Sheet B3
A1: B3 Working with text
A2: Type your formula in each yellow cell. The check below it turns green when your result matches.
A4: Exercise 1 | B4: Tidy up the lead names: remove extra spaces and capitalise each word. Your formula should spill all six names.
A5: Your formula
A6: {=IF(ISBLANK(B5),"",IFERROR(IF(AND(ROWS(_xlfn.ANCHORARRAY(B5))=ROWS(_xlfn.ANCHORARRAY(Answers!$B$57)),COLUMNS(_xlfn.ANCHORARRAY(B5))=COLUMNS(_xlfn.ANCHORARRAY(Answers!$B$57)),AND(_xlfn.ANCHORARRAY(B5)=_xlfn.ANCHORARRAY(Answers!$B$57))),"✓ Correct","Not yet"),"Not yet"))}
A13: Exercise 2 | B13: Get each lead's state code: the part of Location after the comma and space.
A14: Your formula
A15: {=IF(ISBLANK(B14),"",IFERROR(IF(AND(ROWS(_xlfn.ANCHORARRAY(B14))=ROWS(_xlfn.ANCHORARRAY(Answers!$B$64)),COLUMNS(_xlfn.ANCHORARRAY(B14))=COLUMNS(_xlfn.ANCHORARRAY(Answers!$B$64)),AND(_xlfn.ANCHORARRAY(B14)=_xlfn.ANCHORARRAY(Answers!$B$64))),"✓ Correct","Not yet"),"Not yet"))}
A22: Exercise 3 | B22: Get each sales rep's last name from the Name column of the Staff table.
A23: Your formula
A24: {=IF(ISBLANK(B23),"",IFERROR(IF(AND(ROWS(_xlfn.ANCHORARRAY(B23))=ROWS(_xlfn.ANCHORARRAY(Answers!$B$71)),COLUMNS(_xlfn.ANCHORARRAY(B23))=COLUMNS(_xlfn.ANCHORARRAY(Answers!$B$71)),AND(_xlfn.ANCHORARRAY(B23)=_xlfn.ANCHORARRAY(Answers!$B$71))),"✓ Correct","Not yet"),"Not yet"))}
A33: Exercise 4 | B33: List every rep's first name in one cell, separated by a comma and a space.
A34: Your formula
A35: =IF(ISBLANK(B34),"",IF(IFERROR(AND(B34=Answers!$B$80),FALSE),"✓ Correct","Not yet"))
A37: Exercise 5 | B37: Turn the order number SO-1048 into the number 1048, so you could do arithmetic with it.
A38: Your formula
A39: =IF(ISBLANK(B38),"",IF(IFERROR(AND(B38=Answers!$B$82),FALSE),"✓ Correct","Not yet"))

Sheet B4
A1: B4 Dates and times
A2: Type your formula in each yellow cell. The check below it turns green when your result matches.
A4: Exercise 1 | B4: How many orders were placed in March 2026? Use COUNTIFS with a start and end date.
A5: Your formula
A6: =IF(ISBLANK(B5),"",IF(IFERROR(AND(B5=Answers!$B$84),FALSE),"✓ Correct","Not yet"))
A8: Exercise 2 | B8: What is the last day of the month in which the first order was placed? Show it as text in the form 2026-03-31.
A9: Your formula
A10: =IF(ISBLANK(B9),"",IF(IFERROR(AND(B9=Answers!$B$86),FALSE),"✓ Correct","Not yet"))
A12: Exercise 3 | B12: What is the longest time any order took to ship, in days?
A13: Your formula
A14: =IF(ISBLANK(B13),"",IF(IFERROR(AND(B13=Answers!$B$88),FALSE),"✓ Correct","Not yet"))
A16: Exercise 4 | B16: How many working days are there in the second quarter of 2026 (1 April to 30 June)?
A17: Your formula
A18: =IF(ISBLANK(B17),"",IF(IFERROR(AND(B17=Answers!$B$90),FALSE),"✓ Correct","Not yet"))
A20: Exercise 5 | B20: Which year was the longest-serving rep hired? Find the earliest hire date and take its year.
A21: Your formula
A22: =IF(ISBLANK(B21),"",IF(IFERROR(AND(B21=Answers!$B$92),FALSE),"✓ Correct","Not yet"))

Sheet B5
A1: B5 Looking things up
A2: Type your formula in each yellow cell. The check below it turns green when your result matches.
A4: Exercise 1 | B4: What is the cost of product BS-108?
A5: Your formula
A6: =IF(ISBLANK(B5),"",IF(IFERROR(AND(B5=Answers!$B$94),FALSE),"✓ Correct","Not yet"))
A8: Exercise 2 | B8: Look up product BS-200. It doesn't exist, so return the text Not found instead of an error.
A9: Your formula
A10: =IF(ISBLANK(B9),"",IF(IFERROR(AND(B9=Answers!$B$96),FALSE),"✓ Correct","Not yet"))
A12: Exercise 3 | B12: What commission rate applies to sales of 8,450? Use the Tiers table.
A13: Your formula
A14: =IF(ISBLANK(B13),"",IF(IFERROR(AND(B13=Answers!$B$98),FALSE),"✓ Correct","Not yet"))
A16: Exercise 4 | B16: On what date did Grace place her most recent order? Show it as text like 1 Mar 2026.
A17: Your formula
A18: =IF(ISBLANK(B17),"",IF(IFERROR(AND(B17=Answers!$B$100),FALSE),"✓ Correct","Not yet"))
A20: Exercise 5 | B20: What is the order ID of the first Desk Chair order in the North region?
A21: Your formula
A22: =IF(ISBLANK(B21),"",IF(IFERROR(AND(B21=Answers!$B$102),FALSE),"✓ Correct","Not yet"))
A24: Exercise 6 | B24: What is the total revenue from Paper products? Look up each order's category, then sum the matching revenue.
A25: Your formula
A26: =IF(ISBLANK(B25),"",IF(IFERROR(AND(B25=Answers!$B$104),FALSE),"✓ Correct","Not yet"))

Sheet C1
A1: C1 Arrays and spilling
A2: Type your formula in each yellow cell. The check below it turns green when your result matches.
A4: Exercise 1 | B4: Make a column of the numbers 5, 10, 15, … up to 50 with SEQUENCE.
A5: Your formula
A6: {=IF(ISBLANK(B5),"",IFERROR(IF(AND(ROWS(_xlfn.ANCHORARRAY(B5))=ROWS(_xlfn.ANCHORARRAY(Answers!$B$106)),COLUMNS(_xlfn.ANCHORARRAY(B5))=COLUMNS(_xlfn.ANCHORARRAY(Answers!$B$106)),AND(_xlfn.ANCHORARRAY(B5)=_xlfn.ANCHORARRAY(Answers!$B$106))),"✓ Correct","Not yet"),"Not yet"))}
A17: Exercise 2 | B17: List each product's profit margin as a fraction of its price: price minus cost, divided by price. Round to 3 decimal places.
A18: Your formula
A19: {=IF(ISBLANK(B18),"",IFERROR(IF(AND(ROWS(_xlfn.ANCHORARRAY(B18))=ROWS(_xlfn.ANCHORARRAY(Answers!$B$117)),COLUMNS(_xlfn.ANCHORARRAY(B18))=COLUMNS(_xlfn.ANCHORARRAY(Answers!$B$117)),AND(_xlfn.ANCHORARRAY(B18)=_xlfn.ANCHORARRAY(Answers!$B$117))),"✓ Correct","Not yet"),"Not yet"))}
A28: Exercise 3 | B28: Make a grid of order counts: the four regions down the side (North, South, East, West) and the statuses Closed and Open across the top.
A29: Your formula
A30: {=IF(ISBLANK(B29),"",IFERROR(IF(AND(ROWS(_xlfn.ANCHORARRAY(B29))=ROWS(_xlfn.ANCHORARRAY(Answers!$B$126)),COLUMNS(_xlfn.ANCHORARRAY(B29))=COLUMNS(_xlfn.ANCHORARRAY(Answers!$B$126)),AND(_xlfn.ANCHORARRAY(B29)=_xlfn.ANCHORARRAY(Answers!$B$126))),"✓ Correct","Not yet"),"Not yet"))}
A35: Exercise 4 | B35: Spill the full names of the months January to December across one row.
A36: Your formula
A37: {=IF(ISBLANK(B36),"",IFERROR(IF(AND(ROWS(_xlfn.ANCHORARRAY(B36))=ROWS(_xlfn.ANCHORARRAY(Answers!$B$131)),COLUMNS(_xlfn.ANCHORARRAY(B36))=COLUMNS(_xlfn.ANCHORARRAY(Answers!$B$131)),AND(_xlfn.ANCHORARRAY(B36)=_xlfn.ANCHORARRAY(Answers!$B$131))),"✓ Correct","Not yet"),"Not yet"))}
A39: Exercise 5 | B39: What is the total revenue of each quarter so far (Q1 and Q2)? Use SUMIFS with arrays of start and end dates.
A40: Your formula
A41: {=IF(ISBLANK(B40),"",IFERROR(IF(AND(ROWS(_xlfn.ANCHORARRAY(B40))=ROWS(_xlfn.ANCHORARRAY(Answers!$B$133)),COLUMNS(_xlfn.ANCHORARRAY(B40))=COLUMNS(_xlfn.ANCHORARRAY(Answers!$B$133)),AND(_xlfn.ANCHORARRAY(B40)=_xlfn.ANCHORARRAY(Answers!$B$133))),"✓ Correct","Not yet"),"Not yet"))}

Sheet C2
A1: C2 FILTER, SORT and UNIQUE
A2: Type your formula in each yellow cell. The check below it turns green when your result matches.
A4: Exercise 1 | B4: List the order IDs of every Desk Chair order.
A5: Your formula
A6: {=IF(ISBLANK(B5),"",IFERROR(IF(AND(ROWS(_xlfn.ANCHORARRAY(B5))=ROWS(_xlfn.ANCHORARRAY(Answers!$B$136)),COLUMNS(_xlfn.ANCHORARRAY(B5))=COLUMNS(_xlfn.ANCHORARRAY(Answers!$B$136)),AND(_xlfn.ANCHORARRAY(B5)=_xlfn.ANCHORARRAY(Answers!$B$136))),"✓ Correct","Not yet"),"Not yet"))}
A13: Exercise 2 | B13: List the order IDs of closed orders in the North region with at least 10 units.
A14: Your formula
A15: {=IF(ISBLANK(B14),"",IFERROR(IF(AND(ROWS(_xlfn.ANCHORARRAY(B14))=ROWS(_xlfn.ANCHORARRAY(Answers!$B$143)),COLUMNS(_xlfn.ANCHORARRAY(B14))=COLUMNS(_xlfn.ANCHORARRAY(Answers!$B$143)),AND(_xlfn.ANCHORARRAY(B14)=_xlfn.ANCHORARRAY(Answers!$B$143))),"✓ Correct","Not yet"),"Not yet"))}
A20: Exercise 3 | B20: Make an alphabetical list of the products that have been ordered with a discount.
A21: Your formula
A22: {=IF(ISBLANK(B21),"",IFERROR(IF(AND(ROWS(_xlfn.ANCHORARRAY(B21))=ROWS(_xlfn.ANCHORARRAY(Answers!$B$148)),COLUMNS(_xlfn.ANCHORARRAY(B21))=COLUMNS(_xlfn.ANCHORARRAY(Answers!$B$148)),AND(_xlfn.ANCHORARRAY(B21)=_xlfn.ANCHORARRAY(Answers!$B$148))),"✓ Correct","Not yet"),"Not yet"))}
A30: Exercise 4 | B30: How many different reps have sold Notebooks?
A31: Your formula
A32: =IF(ISBLANK(B31),"",IF(IFERROR(AND(B31=Answers!$B$156),FALSE),"✓ Correct","Not yet"))
A34: Exercise 5 | B34: List the product names sorted by cost, cheapest first.
A35: Your formula
A36: {=IF(ISBLANK(B35),"",IFERROR(IF(AND(ROWS(_xlfn.ANCHORARRAY(B35))=ROWS(_xlfn.ANCHORARRAY(Answers!$B$158)),COLUMNS(_xlfn.ANCHORARRAY(B35))=COLUMNS(_xlfn.ANCHORARRAY(Answers!$B$158)),AND(_xlfn.ANCHORARRAY(B35)=_xlfn.ANCHORARRAY(Answers!$B$158))),"✓ Correct","Not yet"),"Not yet"))}
A45: Exercise 6 | B45: Show the order ID and revenue of the five largest orders, largest first.
A46: Your formula
A47: {=IF(ISBLANK(B46),"",IFERROR(IF(AND(ROWS(_xlfn.ANCHORARRAY(B46))=ROWS(_xlfn.ANCHORARRAY(Answers!$B$167)),COLUMNS(_xlfn.ANCHORARRAY(B46))=COLUMNS(_xlfn.ANCHORARRAY(Answers!$B$167)),AND(_xlfn.ANCHORARRAY(B46)=_xlfn.ANCHORARRAY(Answers!$B$167))),"✓ Correct","Not yet"),"Not yet"))}

Sheet C3
A1: C3 Reshaping arrays
A2: Type your formula in each yellow cell. The check below it turns green when your result matches.
A4: Exercise 1 | B4: Show the product name and category of every product, as a two-column table.
A5: Your formula
A6: {=IF(ISBLANK(B5),"",IFERROR(IF(AND(ROWS(_xlfn.ANCHORARRAY(B5))=ROWS(_xlfn.ANCHORARRAY(Answers!$B$173)),COLUMNS(_xlfn.ANCHORARRAY(B5))=COLUMNS(_xlfn.ANCHORARRAY(Answers!$B$173)),AND(_xlfn.ANCHORARRAY(B5)=_xlfn.ANCHORARRAY(Answers!$B$173))),"✓ Correct","Not yet"),"Not yet"))}
A15: Exercise 2 | B15: List the order IDs of the last five orders in the Sales table.
A16: Your formula
A17: {=IF(ISBLANK(B16),"",IFERROR(IF(AND(ROWS(_xlfn.ANCHORARRAY(B16))=ROWS(_xlfn.ANCHORARRAY(Answers!$B$182)),COLUMNS(_xlfn.ANCHORARRAY(B16))=COLUMNS(_xlfn.ANCHORARRAY(Answers!$B$182)),AND(_xlfn.ANCHORARRAY(B16)=_xlfn.ANCHORARRAY(Answers!$B$182))),"✓ Correct","Not yet"),"Not yet"))}
A23: Exercise 3 | B23: Build a two-column table of each rep and their hire year, with the header row Rep and Hired.
A24: Your formula
A25: {=IF(ISBLANK(B24),"",IFERROR(IF(AND(ROWS(_xlfn.ANCHORARRAY(B24))=ROWS(_xlfn.ANCHORARRAY(Answers!$B$188)),COLUMNS(_xlfn.ANCHORARRAY(B24))=COLUMNS(_xlfn.ANCHORARRAY(Answers!$B$188)),AND(_xlfn.ANCHORARRAY(B24)=_xlfn.ANCHORARRAY(Answers!$B$188))),"✓ Correct","Not yet"),"Not yet"))}
A35: Exercise 4 | B35: Lay out the eight product SKUs as a grid of two rows of four.
A36: Your formula
A37: {=IF(ISBLANK(B36),"",IFERROR(IF(AND(ROWS(_xlfn.ANCHORARRAY(B36))=ROWS(_xlfn.ANCHORARRAY(Answers!$B$198)),COLUMNS(_xlfn.ANCHORARRAY(B36))=COLUMNS(_xlfn.ANCHORARRAY(Answers!$B$198)),AND(_xlfn.ANCHORARRAY(B36)=_xlfn.ANCHORARRAY(Answers!$B$198))),"✓ Correct","Not yet"),"Not yet"))}
A40: Exercise 5 | B40: For each region (in the order North, South, East, West), show the region and its number of orders, as a two-column table.
A41: Your formula
A42: {=IF(ISBLANK(B41),"",IFERROR(IF(AND(ROWS(_xlfn.ANCHORARRAY(B41))=ROWS(_xlfn.ANCHORARRAY(Answers!$B$201)),COLUMNS(_xlfn.ANCHORARRAY(B41))=COLUMNS(_xlfn.ANCHORARRAY(Answers!$B$201)),AND(_xlfn.ANCHORARRAY(B41)=_xlfn.ANCHORARRAY(Answers!$B$201))),"✓ Correct","Not yet"),"Not yet"))}

Sheet C4
A1: C4 Naming things with LET
A2: Type your formula in each yellow cell. The check below it turns green when your result matches.
A4: Exercise 1 | B4: Using LET, name the total revenue of closed orders closedTotal, then return it divided by the number of closed orders, rounded to 2 decimals.
A5: Your formula
A6: =IF(ISBLANK(B5),"",IF(IFERROR(AND(B5=Answers!$B$206),FALSE),"✓ Correct","Not yet"))
A8: Exercise 2 | B8: What percentage of all revenue came from the East region? Use LET to name the East total and the overall total, and return the share rounded to 3 decimals.
A9: Your formula
A10: =IF(ISBLANK(B9),"",IF(IFERROR(AND(B9=Answers!$B$208),FALSE),"✓ Correct","Not yet"))
A12: Exercise 3 | B12: Rewrite this formula with LET so the margin calculation appears only once: =IF((SUM(Products[Price])-SUM(Products[Cost]))/SUM(Products[Price])>0.4,"Healthy: "&TEXT((SUM(Products[Price])-SUM(Products[Cost]))/SUM(Products[Price]),"0%"),"Thin")
A13: Your formula
A14: =IF(ISBLANK(B13),"",IF(IFERROR(AND(B13=Answers!$B$210),FALSE),"✓ Correct","Not yet"))
A16: Exercise 4 | B16: List the order IDs of open orders worth more than the average order, using LET to name the average.
A17: Your formula
A18: =IF(ISBLANK(B17),"",IF(IFERROR(AND(B17=Answers!$B$212),FALSE),"✓ Correct","Not yet"))

Sheet C5
A1: C5 Your own functions with LAMBDA
A2: Type your formula in each yellow cell. The check below it turns green when your result matches.
A4: Exercise 1 | B4: Call an unnamed LAMBDA that doubles a number, giving it the input 21.
A5: Your formula
A6: =IF(ISBLANK(B5),"",IF(IFERROR(AND(B5=Answers!$B$214),FALSE),"✓ Correct","Not yet"))
A8: Exercise 2 | B8: What is the price of a Desk Lamp including tax at the default rate? Look up the price, then use WithTax.
A9: Your formula
A10: =IF(ISBLANK(B9),"",IF(IFERROR(AND(B9=Answers!$B$216),FALSE),"✓ Correct","Not yet"))
A12: Exercise 3 | B12: Use MAP to count each rep's orders of any status, in the order of the Staff table.
A13: Your formula
A14: {=IF(ISBLANK(B13),"",IFERROR(IF(AND(ROWS(_xlfn.ANCHORARRAY(B13))=ROWS(_xlfn.ANCHORARRAY(Answers!$B$218)),COLUMNS(_xlfn.ANCHORARRAY(B13))=COLUMNS(_xlfn.ANCHORARRAY(Answers!$B$218)),AND(_xlfn.ANCHORARRAY(B13)=_xlfn.ANCHORARRAY(Answers!$B$218))),"✓ Correct","Not yet"),"Not yet"))}
A23: Exercise 4 | B23: Use QuarterOf on the whole Date column and count how many orders fall in Q2.
A24: Your formula
A25: =IF(ISBLANK(B24),"",IF(IFERROR(AND(B24=Answers!$B$227),FALSE),"✓ Correct","Not yet"))
A27: Exercise 5 | B27: Use SCAN to make a running total of units across all orders, and return just the last five values with TAKE.
A28: Your formula
A29: {=IF(ISBLANK(B28),"",IFERROR(IF(AND(ROWS(_xlfn.ANCHORARRAY(B28))=ROWS(_xlfn.ANCHORARRAY(Answers!$B$229)),COLUMNS(_xlfn.ANCHORARRAY(B28))=COLUMNS(_xlfn.ANCHORARRAY(Answers!$B$229)),AND(_xlfn.ANCHORARRAY(B28)=_xlfn.ANCHORARRAY(Answers!$B$229))),"✓ Correct","Not yet"),"Not yet"))}

Sheet D1
A1: D1 Errors and debugging
A2: Type your formula in each yellow cell. The check below it turns green when your result matches.
A4: Exercise 1 | B4: Divide total revenue by the number of orders in the "Central" region, returning 0 instead of an error when there are none. Don't use IFERROR.
A5: Your formula
A6: =IF(ISBLANK(B5),"",IF(IFERROR(AND(B5=Answers!$B$235),FALSE),"✓ Correct","Not yet"))
A8: Exercise 2 | B8: Look up the price of SKU BS-110, returning the text Discontinued if it isn't found. Catch only the "not found" case.
A9: Your formula
A10: =IF(ISBLANK(B9),"",IF(IFERROR(AND(B9=Answers!$B$237),FALSE),"✓ Correct","Not yet"))
A12: Exercise 3 | B12: List the order IDs of orders over 1,000 units, or the text None if there aren't any.
A13: Your formula
A14: =IF(ISBLANK(B13),"",IF(IFERROR(AND(B13=Answers!$B$239),FALSE),"✓ Correct","Not yet"))
A16: Exercise 4 | B16: Add up the array {5; #DIV/0!; 15; #N/A; 20} while ignoring its errors.
A17: Your formula
A18: =IF(ISBLANK(B17),"",IF(IFERROR(AND(B17=Answers!$B$241),FALSE),"✓ Correct","Not yet"))

Sheet D2
A1: D2 Formulas other people can read
A2: Type your formula in each yellow cell. The check below it turns green when your result matches.
A4: Exercise 1 | B4: Rewrite =SUMIFS(Sales[Revenue],Sales[Region],"North")/SUM(Sales[Revenue])*100 with LET, naming the two totals, and round the percentage to 1 decimal place.
A5: Your formula
A6: =IF(ISBLANK(B5),"",IF(IFERROR(AND(B5=Answers!$B$243),FALSE),"✓ Correct","Not yet"))
A8: Exercise 2 | B8: Rewrite =IF(SUMIFS(Sales[Units],Sales[Rep],"Dev")>100,SUMIFS(Sales[Units],Sales[Rep],"Dev")0.5,SUMIFS(Sales[Units],Sales[Rep],"Dev")0.25) so the SUMIFS appears only once.
A9: Your formula
A10: =IF(ISBLANK(B9),"",IF(IFERROR(AND(B9=Answers!$B$245),FALSE),"✓ Correct","Not yet"))
A12: Exercise 3 | B12: This formula hides the minimum order value inside it: =COUNTIFS(Sales[Revenue],">=100"). Rewrite it to use the named cell MinOrder instead.
A13: Your formula
A14: =IF(ISBLANK(B13),"",IF(IFERROR(AND(B13=Answers!$B$247),FALSE),"✓ Correct","Not yet"))

Sheet D3
A1: D3 Recipe book
A2: Type your formula in each yellow cell. The check below it turns green when your result matches.
A4: Exercise 1 | B4: What share of total units did the West region sell? Round to 3 decimal places.
A5: Your formula
A6: =IF(ISBLANK(B5),"",IF(IFERROR(AND(B5=Answers!$B$249),FALSE),"✓ Correct","Not yet"))
A8: Exercise 2 | B8: List the two cheapest products by price, cheapest first.
A9: Your formula
A10: {=IF(ISBLANK(B9),"",IFERROR(IF(AND(ROWS(_xlfn.ANCHORARRAY(B9))=ROWS(_xlfn.ANCHORARRAY(Answers!$B$251)),COLUMNS(_xlfn.ANCHORARRAY(B9))=COLUMNS(_xlfn.ANCHORARRAY(Answers!$B$251)),AND(_xlfn.ANCHORARRAY(B9)=_xlfn.ANCHORARRAY(Answers!$B$251))),"✓ Correct","Not yet"),"Not yet"))}
A13: Exercise 3 | B13: Which reps have never had a cancelled order? List them in Staff table order.
A14: Your formula
A15: {=IF(ISBLANK(B14),"",IFERROR(IF(AND(ROWS(_xlfn.ANCHORARRAY(B14))=ROWS(_xlfn.ANCHORARRAY(Answers!$B$254)),COLUMNS(_xlfn.ANCHORARRAY(B14))=COLUMNS(_xlfn.ANCHORARRAY(Answers!$B$254)),AND(_xlfn.ANCHORARRAY(B14)=_xlfn.ANCHORARRAY(Answers!$B$254))),"✓ Correct","Not yet"),"Not yet"))}
A22: Exercise 4 | B22: What product did Chloe sell most recently?
A23: Your formula
A24: =IF(ISBLANK(B23),"",IF(IFERROR(AND(B23=Answers!$B$261),FALSE),"✓ Correct","Not yet"))
A26: Exercise 5 | B26: Show the order ID SO-1001 with its number part padded to six digits: SO-001001.
A27: Your formula
A28: =IF(ISBLANK(B27),"",IF(IFERROR(AND(B27=Answers!$B$263),FALSE),"✓ Correct","Not yet"))
